<?xml version="1.0"?>
<robot name="create">
  <material name="grey">
    <color rgba="0.7 0.7 0.7 1.0"/>
  </material>
  <link name="base">
    <inertial>
      <origin xyz="0.001453 -0.000453 0.029787" rpy="0 0 0"/>
      <inertia ixx="0.058640" ixy="0.000124" ixz="0.000615" iyy="0.058786" iyz="0.000014" izz="1.532440"/>
      <mass value="2.234000"/>
    </inertial>
    <collision name="base_collision">
      <origin xyz="0 0 0.047800" rpy="0 0 0"/>
      <geometry>
        <cylinder radius="0.016495" length="0.061163"/>
      </geometry>
    </collision>
    <visual name="base_visual">
      <origin xyz="0 0 0.047800" rpy="0 0 0"/>
      <geometry>
        <mesh filename="package://create_description/meshes/create_body.dae"/>
      </geometry>
    </visual>
    <collision name="front_wheel_collision">
      <origin xyz="0.130000 0 0.017000" rpy="0 1.570700 1.570700"/>
      <geometry>
        <sphere radius="0.018000"/>
      </geometry>
      <gazebo>
      <surface>
	      <friction>
	      <ode>
            <mu>0</mu>
            <mu2>0</mu2>
            <fdir1>0 0 0</fdir1>
            <slip1>0</slip1>
            <slip2>0</slip2>
          </ode>
        </friction>
      </surface>
    </gazebo>
    </collision>
    <visual name="front_wheel_visual">
      <origin xyz="0.130000 0 0.017000" rpy="0 1.570700 1.570700"/>
      <geometry>
        <sphere radius="0.009000"/>
      </geometry>
      <material name="grey"/>
    </visual>
    <collision name="rear_wheel_collision">
      <origin xyz="-0.13 0 0.017" rpy="0 1.5707 1.5707"/>
      <geometry>
        <sphere radius="0.015000"/>
      </geometry>
      <surface>
        <friction>
          <ode>
            <mu>0</mu>
            <mu2>0</mu2>
            <fdir1>0 0 0</fdir1>
            <slip1>0</slip1>
            <slip2>0</slip2>
          </ode>
        </friction>
      </surface>
    </collision>
    <visual name="rear_wheel_visual">
      <origin xyz="-0.130000 0 0.017000" rpy="0 1.570700 1.570700"/>
      <geometry>
        <sphere radius="0.007500"/>
      </geometry>
      <material name="grey"/>
    </visual>
    <!--<sensor name="left_cliff_sensor" type="ray">
      <origin xyz="0.070000 0.140000 0.027000" rpy="0 1.570790 0"/>
      <ray>
        <scan>
          <horizontal>
            <samples>1</samples>
            <resolution>1.000000</resolution>
            <min_angle>0</min_angle>
            <max_angle>0</max_angle>
          </horizontal>
        </scan>
        <range>
          <min>0.010000</min>
          <max>0.040000</max>
          <resolution>0.100000</resolution>
        </range>
      </ray>
    </sensor>
    <sensor name="leftfront_cliff_sensor" type="ray">
      <origin xyz="0.150000 0.040000 0.027000" rpy="0 1.570790 0"/>
      <ray>
        <scan>
          <horizontal>
            <samples>1</samples>
            <resolution>1.000000</resolution>
            <min_angle>0</min_angle>
            <max_angle>0</max_angle>
          </horizontal>
        </scan>
        <range>
          <min>0.010000</min>
          <max>0.040000</max>
          <resolution>0.100000</resolution>
        </range>
      </ray>
    </sensor>
    <sensor name="right_cliff_sensor" type="ray">
      <origin xyz="0.070000 -0.140000 0.027000" rpy="0 1.570790 0"/>
      <ray>
        <scan>
          <horizontal>
            <samples>1</samples>
            <resolution>1.000000</resolution>
            <min_angle>0</min_angle>
            <max_angle>0</max_angle>
          </horizontal>
        </scan>
        <range>
          <min>0.010000</min>
          <max>0.040000</max>
          <resolution>0.100000</resolution>
        </range>
      </ray>
    </sensor>
    <sensor name="rightfront_cliff_sensor" type="ray">
      <origin xyz="0.150000 -0.040000 0.027000" rpy="0 1.570790 0"/>
      <ray>
        <scan>
          <horizontal>
            <samples>1</samples>
            <resolution>1.000000</resolution>
            <min_angle>0</min_angle>
            <max_angle>0</max_angle>
          </horizontal>
        </scan>
        <range>
          <min>0.010000</min>
          <max>0.040000</max>
          <resolution>0.100000</resolution>
        </range>
      </ray>
    </sensor>
    <sensor name="wall_sensor" type="ray">
      <origin xyz="0.090000 -0.120000 0.059000" rpy="0 0 -1.000000"/>
      <ray>
        <scan>
          <horizontal>
            <samples>1</samples>
            <resolution>1.000000</resolution>
            <min_angle>0</min_angle>
            <max_angle>0</max_angle>
          </horizontal>
        </scan>
        <range>
          <min>0.016000</min>
          <max>0.040000</max>
          <resolution>0.100000</resolution>
        </range>
      </ray>
    </sensor>-->
  </link>
  <link name="left_wheel">
    <origin xyz="0 0.130000 0.032000" rpy="0 0 0"/>
    <inertial>
      <inertia ixx="0.001000" ixy="0" ixz="0" iyy="0.001000" iyz="0" izz="0.001000"/>
      <mass value="0.010000"/>
    </inertial>
    <collision name="collision">
      <origin xyz="0 0 0" rpy="0 1.570700 1.570700"/>
      <geometry>
        <cylinder radius="0.033000" length="0.023000"/>
      </geometry>
      <surface>
        <friction>
          <ode>
            <mu>10</mu>
            <mu2>10</mu2>
            <fdir1>0 0 0</fdir1>
            <slip1>0</slip1>
            <slip2>0</slip2>
          </ode>
        </friction>
      </surface>
    </collision>
    <visual name="visual">
      <origin xyz="0 0 0" rpy="0 1.570700 1.570700"/>
      <geometry>
        <cylinder radius="0.033000" length="0.023000"/>
      </geometry>
    </visual>
  </link>
  <link name="right_wheel">
    <origin xyz="0 -0.130000 0.032000" rpy="0 0 0"/>
    <inertial>
      <inertia ixx="0.001000" ixy="0" ixz="0" iyy="0.001000" iyz="0" izz="0.001000"/>
      <mass value="0.010000"/>
    </inertial>
    <collision name="collision">
      <origin xyz="0 0 0" rpy="0 1.570700 1.570700"/>
      <geometry>
        <cylinder radius="0.033000" length="0.023000"/>
      </geometry>
      <surface>
        <friction>
          <ode>
            <mu>10</mu>
            <mu2>10</mu2>
            <fdir1>0 0 0</fdir1>
            <slip1>0</slip1>
            <slip2>0</slip2>
          </ode>
        </friction>
      </surface>
    </collision>
    <visual name="visual">
      <origin xyz="0 0 0" rpy="0 1.570700 1.570700"/>
      <geometry>
        <cylinder radius="0.033000" length="0.023000"/>
      </geometry>
    </visual>
  </link>
  <joint name="left_wheel" type="continuous">
    <parent link="base"/>
    <child link="left_wheel"/>
    <axis xyz="0 1 0"/>
  </joint>
  <joint name="right_wheel" type="continuous">
    <parent link="base"/>
    <child link="right_wheel"/>
    <axis xyz="0 1 0"/>
  </joint>
  <transmission name="left_wheel_trans" type="SimpleTransmission">
    <type>transmission_interface/SimpleTransmission</type>
    <actuator name="left_wheel_motor">
      <mechanicalReduction>1</mechanicalReduction>
    </actuator>
    <joint name="left_wheel">
      <hardwareInterface>VelocityJointInterface</hardwareInterface>
    </joint>
  </transmission>
  <transmission name="right_wheel_trans" type="SimpleTransmission">
    <type>transmission_interface/SimpleTransmission</type>
    <actuator name="right_wheel_motor">
      <mechanicalReduction>1</mechanicalReduction>
    </actuator>
    <joint name="right_wheel">
      <hardwareInterface>VelocityJointInterface</hardwareInterface>
    </joint>
  </transmission>
</robot>
